Workbook

Sheet Instructions
B1: 2026 NA Revenue Tracking — User Guide
B2: Questions? Contact Pedro
B3: HOW IT WORKS
B4: Forecast Input | C4: The only place anyone types. Vertical owners update forecast weekly and actuals monthly.
B5: Vertical tabs (Rotowire, Sports Affiliate, etc.) | C5: Read-only summaries. Pull from Forecast Input automatically. Show full detail + variances.
B6: Executive Dashboard | C6: Full-year snapshot + traffic light attainment. Auto-updates.
B7: VERTICAL OWNERS — WEEKLY (BY WEDNESDAY)
B8: Step 1 | C8: Go to Forecast Input tab.
B9: Step 2 | C9: Find your vertical section and the 🟡 yellow Forecast rows. Update each open month with your best current estimate.
B10: Step 3 | C10: Save and notify #sds-budget-owners Slack channel
B11: Step 4 | C11: Enter confirmed Actuals in the 🟦 teal rows on the Forecast Input tab after each month closes.
B12: DEFINITIONS
B13: 🟡 Forecast (yellow) | C13: Owner's weekly best estimate. Update every Wednesday.
B14: 🟦 Actual 26' (teal) | C14: Confirmed 2026 revenue entered after each month closes.
B15: Actual 25' | C15: Prior year actuals — locked reference, not editable.
B16: Budget | C16: Annual budget set in Dec 2025. Locked
B17: Target | C17: Stretch goal. Locked.
B18: Run-Rate ★ | C18: Closed Month Actuals + Forecast. Directional only until more months confirm.
B19: 🟢 On Track | C19: Forecast ≥ Budget.
B20: 🟡 Watch | C20: Forecast within 10% below Budget.
B21: 🔴 At Risk | C21: Forecast more than 10% below Budget — escalate.

Sheet Forecast Input
A1: 2026 SDS Revenue — Forecast Input
A2: 🟡 Yellow = Forecast (vertical owners — update weekly by Wednesday) · 🟦 Teal = Actuals (vertical owners — enter after month close)
A3: VERTICAL | B3: SUB-LINE | C3: METRIC | D3: Jan | E3: Feb | F3: Mar | G3: Apr | H3: May | I3: Jun | J3: Jul | K3: Aug | L3: Sep | M3: Oct | N3: Nov | O3: Dec | P3: FULL YEAR
A4: ROTOWIRE
A5: Rotowire | B5: B2C Subs | C5: Actual 26 🟦 | D5: 474038.26 | E5: 459134.72 | F5: 552360.2 | P5: =SUM(D5:O5) -> 1485533.2
B6: B2C Subs | C6: Forecast 🟡 | D6: 484326 | E6: =446408-3000 -> 443408 | F6: =543544-10000+2000-4000 -> 531544 | G6: =478073-5000-14000 -> 459073 | H6: =462554-10000 -> 452554 | I6: =487438-9000 -> 478438 | J6: =482501+9000 -> 491501 | K6: 751620 | L6: 784277 | M6: 731746 | N6: 714855 | O6: 681276 | P6: =SUM(D6:O6) -> 7004618
B7: Advertising | C7: Actual 26 🟦 | D7: 111988.73 | E7: 103856.8 | F7: 134400.81 | P7: =SUM(D7:O7) -> 350246.34
B8: Advertising | C8: Forecast 🟡 | D8: 73000 | E8: =67000+12000 -> 79000 | F8: =104000+5000+6000 -> 115000 | G8: 114000 | H8: 79000 | I8: 74000 | J8: 82000 | K8: 124000 | L8: 124000 | M8: 107000 | N8: 124000 | O8: 124000 | P8: =SUM(D8:O8) -> 1219000
B9: B2B Content | C9: Actual 26 🟦 | D9: 243987.32 | E9: 236446.5 | F9: 248430.63 | P9: =SUM(D9:O9) -> 728864.45 | Q9: Feb26 is a bit low because finance did not include DraftKings deal here. Getting to the bottom of why.
B10: B2B Content | C10: Forecast 🟡 | D10: 273000 | E10: =274000-15000 -> 259000 | F10: =270000-8000-4000-10000 -> 248000 | G10: =291000-9000-15000-8000-5000 -> 254000 | H10: =302000-15000-10000-8000-5000 -> 264000 | I10: =317000-20000-8000-10000-5000 -> 274000 | J10: =321000-10000 -> 311000 | K10: =326000-5000 -> 321000 | L10: =329000-5000 -> 324000 | M10: =335000-5000 -> 330000 | N10: =338000-5000 -> 333000 | O10: =342000-5000 -> 337000 | P10: =SUM(D10:O10) -> 3528000
B11: Rotowire Affiliate | C11: Actual 26 🟦 | D11: 373629.35 | E11: 478517.09 | F11: 568834.08 | P11: =SUM(D11:O11) -> 1420980.5
B12: Rotowire Affiliate | C12: Forecast 🟡 | D12: 390000 | E12: 350000 | F12: 600000 | G12: 500000 | H12: 350000 | I12: 350000 | J12: 350000 | K12: 500000 | L12: 600000 | M12: 500000 | N12: 500000 | O12: 500000 | P12: =SUM(D12:O12) -> 5490000 | Q12: Adjusted a few months in the summer down a bit as well as the last three months of the year. Nothing dramatic, just learning more about the seasonality of a site like RotoWire.
A13: SPORTS AFFILIATE
A14: Sports Affiliate | B14: Bookies US | C14: Actual 26 🟦 | D14: -3260.2155 | E14: 44660 | F14: 2249 | P14: =SUM(D14:O14) -> 43648.784
B15: Bookies US | C15: Forecast 🟡 | D15: 30000 | E15: 37500 | F15: 15000 | G15: 55000 | H15: 55000 | I15: 55000 | J15: 95000 | K15: 105000 | L15: 150000 | M15: 105000 | N15: 105000 | O15: 105000 | P15: =SUM(D15:O15) -> 912500
B16: Bookies UK | C16: Actual 26 🟦 | D16: 212757.88 | E16: 148559.81 | F16: 9433 | P16: =SUM(D16:O16) -> 370750.69
B17: Bookies UK | C17: Forecast 🟡 | D17: 175000 | E17: 177000 | F17: 150000 | G17: 150000 | H17: 150000 | I17: 150000 | J17: 150000 | K17: 215000 | L17: 205000 | M17: 200000 | N17: 200000 | O17: 200000 | P17: =SUM(D17:O17) -> 2122000
B18: Bookies IE | C18: Actual 26 🟦 | D18: 2024.5313 | E18: 6347.5797 | F18: 6358 | P18: =SUM(D18:O18) -> 14730.111
B19: Bookies IE | C19: Forecast 🟡 | D19: 12500 | E19: 13500 | F19: 13000 | G19: 13500 | H19: 12000 | I19: 13500 | J19: 12000 | K19: 14000 | L19: 16000 | M19: 10000 | N19: 10000 | O19: 10000 | P19: =SUM(D19:O19) -> 150000
B20: Bookies IN | C20: Actual 26 🟦 | D20: 5566.1161 | E20: 14370.106 | F20: 7935 | P20: =SUM(D20:O20) -> 27871.222
B21: Bookies IN | C21: Forecast 🟡 | D21: 10000 | E21: 10000 | F21: 8500 | G21: 8000 | H21: 8000 | I21: 8000 | J21: 8000 | K21: 8000 | L21: 8000 | M21: 8000 | N21: 8000 | O21: 8000 | P21: =SUM(D21:O21) -> 100500
B22: Bookies CA | C22: Actual 26 🟦 | D22: 9408.0531 | E22: 4565.4974 | F22: 14841 | P22: =SUM(D22:O22) -> 28814.55
B23: Bookies CA | C23: Forecast 🟡 | D23: 17500 | E23: 15000 | F23: 14500 | G23: 14500 | H23: 14500 | I23: 15000 | J23: 16500 | K23: 16500 | L23: 20000 | M23: 18500 | N23: 18000 | O23: 18000 | P23: =SUM(D23:O23) -> 198500
B24: Bookies AU | C24: Actual 26 🟦 | D24: 2960.88 | E24: 687.37603 | F24: -1533 | P24: =SUM(D24:O24) -> 2115.2561
B25: Bookies AU | C25: Forecast 🟡 | D25: 1500 | E25: 1500 | F25: 1500 | G25: 1500 | H25: 1500 | I25: 1500 | J25: 1500 | K25: 1500 | L25: 1500 | M25: 1500 | N25: 1500 | O25: 1500 | P25: =SUM(D25:O25) -> 18000
B26: Bookies NZ | C26: Actual 26 🟦 | D26: 1721.4416 | E26: 4112.945 | F26: 4550 | P26: =SUM(D26:O26) -> 10384.387
B27: Bookies NZ | C27: Forecast 🟡 | D27: 10000 | E27: 5000 | F27: 10000 | G27: 7500 | H27: 8000 | I27: 8000 | J27: 8500 | K27: 8500 | L27: 7500 | M27: 10000 | N27: 10000 | O27: 8500 | P27: =SUM(D27:O27) -> 101500
B28: Bookies MX | C28: Actual 26 🟦 | D28: 8337.3099 | E28: 3992.0958 | F28: 1794 | P28: =SUM(D28:O28) -> 14123.406
B29: Bookies MX | C29: Forecast 🟡 | D29: 3000 | E29: 8000 | F29: 8000 | G29: 5500 | H29: 5500 | I29: 5500 | J29: 5500 | K29: 5500 | L29: 5500 | M29: 5500 | N29: 5500 | O29: 5500 | P29: =SUM(D29:O29) -> 68500
B30: Bookies NG | C30: Actual 26 🟦 | D30: 0.648964 | E30: 0 | P30: =SUM(D30:O30) -> 0.648964
B31: Bookies NG | C31: Forecast 🟡 | P31: =SUM(D31:O31) -> 0 | Q31: Not market we are focusing on. Pulling out of mkt.
B32: Bookies NL | C32: Actual 26 🟦 | D32: 601.71932 | E32: 224.09292 | F32: 15 | P32: =SUM(D32:O32) -> 840.81223
B33: Bookies NL | C33: Forecast 🟡 | D33: 1500 | E33: 1500 | F33: 1500 | G33: 1500 | H33: 1500 | I33: 1500 | J33: 1500 | K33: 1500 | L33: 1500 | M33: 1500 | N33: 1500 | O33: 1500 | P33: =SUM(D33:O33) -> 18000
B34: Bookies BR | C34: Actual 26 🟦 | D34: 111.69258 | E34: 260.21518 | F34: -77 | P34: =SUM(D34:O34) -> 294.90776
B35: Bookies BR | C35: Forecast 🟡 | D35: 100 | E35: 100 | F35: 100 | G35: 100 | H35: 100 | I35: 100 | J35: 100 | K35: 100 | L35: 100 | M35: 100 | N35: 100 | O35: 100 | P35: =SUM(D35:O35) -> 1200 | Q35: Most likely out of market by end of Q1
B36: Bookies GX | C36: Actual 26 🟦 | D36: 167.97545 | E36: 546 | F36: 651 | P36: =SUM(D36:O36) -> 1364.9755
B37: Bookies GX | C37: Forecast 🟡 | D37: 100 | E37: 100 | F37: 100 | G37: 100 | H37: 100 | I37: 100 | J37: 100 | K37: 100 | L37: 100 | M37: 100 | N37: 100 | O37: 100 | P37: =SUM(D37:O37) -> 1200
B38: Bookies ES | C38: Actual 26 🟦 | E38: 5.797546 | F38: 289 | P38: =SUM(D38:O38) -> 294.79755
B39: Bookies ES | C39: Forecast 🟡 | D39: 100 | E39: 100 | F39: 100 | G39: 500 | H39: 500 | I39: 500 | J39: 1000 | K39: 1000 | L39: 1000 | M39: 1000 | N39: 1000 | O39: 1000 | P39: =SUM(D39:O39) -> 7800
B40: Bookmakers | C40: Actual 26 🟦 | D40: -13263.989 | E40: 17347.598 | F40: 14186 | P40: =SUM(D40:O40) -> 18269.609
...

Sheet Management View--->

Sheet Executive Dashboard
A1: 2026 SDS Revenue Forecast
A2: FULL-YEAR SUMMARY — ALL VERTICALS COMBINED
B3: 2025 Actuals | C3: 2026 Budget | D3: 2026 Target | E3: 2026 Forecast | F3: 26F vs 25A
A4: Total SDS | B4: =B82 -> 57053617 | C4: =SUM(B11:B16) -> 68369348 | D4: =I17 -> 69382852 | E4: =Forecast!N65 -> 67162174 | F4: =(E4-B4)/B4 -> 0.17717645
A5: Forecast = Actuals + Forecast · Updates automatically as actuals are entered
A8: BUDGET vs FORECAST ANNUAL | H8: TARGET vs FORECAST | N8: Comments
A9: Are we on track to hit our committed plan? | H9: Based on actuals + forecasted months
A10: VERTICAL | B10: 2026 Budget | C10: Forecast | D10: $ Difference | E10: % Diff | F10: STATUS | H10: VERTICAL | I10: 2026 Target | J10: Forecast | K10: $ Difference | L10: % Diff | M10: STATUS
A11: Rotowire | B11: 14045617 | C11: =J11 -> 17380964 | D11: =IFERROR(C11-B11,0) -> 3335347.5 | E11: =IFERROR((C11-B11)/ABS(B11),0) -> 0.23746536 | F11: =IF(E11>=0,"🟢 On Track",IF(E11>=-0.1,"🟡 Watch","🔴 At Risk")) -> 🟢 On Track | H11: Rotowire | I11: 14850000 | J11: =Forecast!N8 -> 17380964 | K11: =IFERROR(J11-I11,0) -> 2530964.5 | L11: =IFERROR((J11-I11)/ABS(I11),0) -> 0.17043532 | M11: =IF(L11>=0,"🟢 On Track",IF(L11>=-0.1,"🟡 Watch","🔴 At Risk")) -> 🟢 On Track | N11: Big boost in affiliate revenue continues. Subs also on a steady positive trend in early March, a good start considering sub growth is typically higher in the back half of the month (more renewals in system). Affiliate 3/16: Commercial reported a solid first half of the month so upped the the forecasts for the summer months a bit as I feel the floor continues to rise even with sports out of season.
A12: Bookies | B12: 6233352 | C12: =J12 -> 3742664.2 | D12: =IFERROR(C12-B12,0) -> -2490687.8 | E12: =IFERROR((C12-B12)/ABS(B12),0) -> -0.39957439 | F12: =IF(E12>=0,"🟢 On Track",IF(E12>=-0.1,"🟡 Watch","🔴 At Risk")) -> 🔴 At Risk | H12: Bookies | I12: 6233352 | J12: =Forecast!N25 -> 3742664.2 | K12: =IFERROR(J12-I12,0) -> -2490687.8 | L12: =IFERROR((J12-I12)/ABS(I12),0) -> -0.39957439 | M12: =IF(L12>=0,"🟢 On Track",IF(L12>=-0.1,"🟡 Watch","🔴 At Risk")) -> 🔴 At Risk | N12: 4/15 UK saw large negative rev share hit from William Hill in March. Lowering UK slightly, but seemingly a one-off.
A13: Partnerships | B13: 999996 | C13: =J13 -> 5611993.2 | D13: =IFERROR(C13-B13,0) -> 4611997.2 | E13: =IFERROR((C13-B13)/ABS(B13),0) -> 4.6120157 | F13: =IF(E13>=0,"🟢 On Track",IF(E13>=-0.1,"🟡 Watch","🔴 At Risk")) -> 🟢 On Track | H13: Partnerships | I13: 1258000 | J13: =Forecast!N28 -> 5611993.2 | K13: =IFERROR(J13-I13,0) -> 4353993.2 | L13: =IFERROR((J13-I13)/ABS(I13),0) -> 3.4610439 | M13: =IF(L13>=0,"🟢 On Track",IF(L13>=-0.1,"🟡 Watch","🔴 At Risk")) -> 🟢 On Track | N13: 4/1: Commercial reported a solid first half of the month so upped the March and April forecasts a bit.
A14: Local | B14: 3731000 | C14: =J14 -> 1233562.8 | D14: =IFERROR(C14-B14,0) -> -2497437.2 | E14: =IFERROR((C14-B14)/ABS(B14),0) -> -0.66937474 | F14: =IF(E14>=0,"🟢 On Track",IF(E14>=-0.1,"🟡 Watch","🔴 At Risk")) -> 🔴 At Risk | H14: Local | I14: 3731000 | J14: =Forecast!N57 -> 1233562.8 | K14: =IFERROR(J14-I14,0) -> -2497437.2 | L14: =IFERROR((J14-I14)/ABS(I14),0) -> -0.66937474 | M14: =IF(L14>=0,"🟢 On Track",IF(L14>=-0.1,"🟡 Watch","🔴 At Risk")) -> 🔴 At Risk | N14: 4/1: No Changes
A15: OddsJam | B15: 20765167 | C15: =J15 -> 16915715 | D15: =IFERROR(C15-B15,0) -> -3849452.3 | E15: =IFERROR((C15-B15)/ABS(B15),0) -> -0.18538027 | F15: =IF(E15>=0,"🟢 On Track",IF(E15>=-0.1,"🟡 Watch","🔴 At Risk")) -> 🔴 At Risk | H15: OddsJam | I15: 19027500 | J15: =Forecast!N59+Forecast!N60+Forecast!N61 -> 16915715 | K15: =IFERROR(J15-I15,0) -> -2111785.3 | L15: =IFERROR((J15-I15)/ABS(I15),0) -> -0.11098596 | M15: =IF(L15>=0,"🟢 On Track",IF(L15>=-0.1,"🟡 Watch","🔴 At Risk")) -> 🔴 At Risk | N15: 4/22: $71k of contraction on prediction insiders bringing MRR down from $165k to $105k. Combined with churn from seasonality.
A16: OpticOdds | B16: 22594216 | C16: =J16 -> 22277275 | D16: =IFERROR(C16-B16,0) -> -316941.46 | E16: =IFERROR((C16-B16)/ABS(B16),0) -> -0.014027548 | F16: =IF(E16>=0,"🟢 On Track",IF(E16>=-0.1,"🟡 Watch","🔴 At Risk")) -> 🟡 Watch | H16: OpticOdds | I16: 24283000 | J16: =Forecast!N63+Forecast!N62 -> 22277275 | K16: =IFERROR(J16-I16,0) -> -2005725.5 | L16: =IFERROR((J16-I16)/ABS(I16),0) -> -0.082597927 | M16: =IF(L16>=0,"🟢 On Track",IF(L16>=-0.1,"🟡 Watch","🔴 At Risk")) -> 🟡 Watch
A17: TOTAL SDS | B17: =SUM(B11:B16) -> 68369348 | C17: =SUM(C11:C16) -> 67162174 | D17: =IFERROR(C17-B17,0) -> -1207174.1 | E17: =IFERROR((C17-B17)/ABS(B17),0) -> -0.017656656 | F17: =IF(E17>=0,"🟢 On Track",IF(E17>=-0.1,"🟡 Watch","🔴 At Risk")) -> 🟡 Watch | H17: TOTAL SDS | I17: =SUM(I11:I16) -> 69382852 | J17: =SUM(J11:J16) -> 67162174 | K17: =IFERROR(J17-I17,0) -> -2220678.1 | L17: =IFERROR((J17-I17)/ABS(I17),0) -> -0.032006151 | M17: =IF(L17>=0,"🟢 On Track",IF(L17>=-0.1,"🟡 Watch","🔴 At Risk")) -> 🟡 Watch
A18: 🟢 Forecast ≥ Budget · 🟡 Forecast within 10% below Budget · 🔴 Forecast more than 10% below Budget | H18: 🟢 Rolling Forecast ≥ Budget · 🟡 Rolling Forecast within 10% below Budget · 🔴 Rolling Forecast more than 10% below Budget
A21: BUDGET vs FORECAST Q1 | H21: TARGET vs FORECAST Q1
A22: Based on actuals + forecasted months | H22: Based on actuals + forecasted months
A23: VERTICAL | B23: 2026 Budget | C23: Forecast | D23: $ Difference | E23: % Diff | F23: STATUS | H23: VERTICAL | I23: 2026 Target | J23: Forecast | K23: $ Difference | L23: % Diff | M23: STATUS
A24: Rotowire | B24: 2993779 | C24: =Forecast!B8+Forecast!C8+Forecast!D8 -> 3985624.5 | D24: =IFERROR(C24-B24,0) -> 991845.49 | E24: =IFERROR((C24-B24)/ABS(B24),0) -> 0.33130217 | F24: =IF(E24>=0,"🟢 On Track",IF(E24>=-0.1,"🟡 Watch","🔴 At Risk")) -> 🟢 On Track | H24: Rotowire | I24: 3165230.7 | J24: =C24 -> 3985624.5 | K24: =IFERROR(J24-I24,0) -> 820393.79 | L24: =IFERROR((J24-I24)/ABS(I24),0) -> 0.25918925 | M24: =IF(L24>=0,"🟢 On Track",IF(L24>=-0.1,"🟡 Watch","🔴 At Risk")) -> 🟢 On Track
A25: Bookies | B25: 1330788 | C25: =Forecast!B25+Forecast!C25+Forecast!D25 -> 540375.15 | D25: =IFERROR(C25-B25,0) -> -790412.85 | E25: =IFERROR((C25-B25)/ABS(B25),0) -> -0.59394347 | F25: =IF(E25>=0,"🟢 On Track",IF(E25>=-0.1,"🟡 Watch","🔴 At Risk")) -> 🔴 At Risk | H25: Bookies | I25: 1330788 | J25: =C25 -> 540375.15 | K25: =IFERROR(J25-I25,0) -> -790412.85 | L25: =IFERROR((J25-I25)/ABS(I25),0) -> -0.59394347 | M25: =IF(L25>=0,"🟢 On Track",IF(L25>=-0.1,"🟡 Watch","🔴 At Risk")) -> 🔴 At Risk
A26: Partnerships | B26: 249999 | C26: =Forecast!B28+Forecast!C28+Forecast!D28 -> 1861993.2 | D26: =IFERROR(C26-B26,0) -> 1611994.2 | E26: =IFERROR((C26-B26)/ABS(B26),0) -> 6.4480026 | F26: =IF(E26>=0,"🟢 On Track",IF(E26>=-0.1,"🟡 Watch","🔴 At Risk")) -> 🟢 On Track | H26: Partnerships | I26: 314500 | J26: =C26 -> 1861993.2 | K26: =IFERROR(J26-I26,0) -> 1547493.2 | L26: =IFERROR((J26-I26)/ABS(I26),0) -> 4.9204871 | M26: =IF(L26>=0,"🟢 On Track",IF(L26>=-0.1,"🟡 Watch","🔴 At Risk")) -> 🟢 On Track
A27: Local | B27: 949500 | C27: =Forecast!B57+Forecast!C57+Forecast!D57 -> 365162.84 | D27: =IFERROR(C27-B27,0) -> -584337.16 | E27: =IFERROR((C27-B27)/ABS(B27),0) -> -0.61541565 | F27: =IF(E27>=0,"🟢 On Track",IF(E27>=-0.1,"🟡 Watch","🔴 At Risk")) -> 🔴 At Risk | H27: Local | I27: 949500 | J27: =C27 -> 365162.84 | K27: =IFERROR(J27-I27,0) -> -584337.16 | L27: =IFERROR((J27-I27)/ABS(I27),0) -> -0.61541565 | M27: =IF(L27>=0,"🟢 On Track",IF(L27>=-0.1,"🟡 Watch","🔴 At Risk")) -> 🔴 At Risk
A28: OddsJam | B28: 5470003 | C28: =SUM(Forecast!B59:D61) -> 4471835.7 | D28: =IFERROR(C28-B28,0) -> -998167.28 | E28: =IFERROR((C28-B28)/ABS(B28),0) -> -0.18248021 | F28: =IF(E28>=0,"🟢 On Track",IF(E28>=-0.1,"🟡 Watch","🔴 At Risk")) -> 🔴 At Risk | H28: OddsJam | I28: 5012263.2 | J28: =C28 -> 4471835.7 | K28: =IFERROR(J28-I28,0) -> -540427.46 | L28: =IFERROR((J28-I28)/ABS(I28),0) -> -0.10782105 | M28: =IF(L28>=0,"🟢 On Track",IF(L28>=-0.1,"🟡 Watch","🔴 At Risk")) -> 🔴 At Risk
A29: OpticOdds | B29: 4749914 | C29: =SUM(Forecast!B62:D63) -> 4731775.5 | D29: =IFERROR(C29-B29,0) -> -18138.459 | E29: =IFERROR((C29-B29)/ABS(B29),0) -> -0.0038186921 | F29: =IF(E29>=0,"🟢 On Track",IF(E29>=-0.1,"🟡 Watch","🔴 At Risk")) -> 🟡 Watch | H29: OpticOdds | I29: 5104942 | J29: =C29 -> 4731775.5 | K29: =IFERROR(J29-I29,0) -> -373166.44 | L29: =IFERROR((J29-I29)/ABS(I29),0) -> -0.073099056 | M29: =IF(L29>=0,"🟢 On Track",IF(L29>=-0.1,"🟡 Watch","🔴 At Risk")) -> 🟡 Watch
A30: TOTAL SDS | B30: =SUM(B24:B29) -> 15743983 | C30: =SUM(C24:C29) -> 15956767 | D30: =IFERROR(C30-B30,0) -> 212783.95 | E30: =IFERROR((C30-B30)/ABS(B30),0) -> 0.013515255 | F30: =IF(E30>=0,"🟢 On Track",IF(E30>=-0.1,"🟡 Watch","🔴 At Risk")) -> 🟢 On Track | H30: TOTAL SDS | I30: =SUM(I24:I29) -> 15877224 | J30: =SUM(J24:J29) -> 15956767 | K30: =IFERROR(J30-I30,0) -> 79543.088 | L30: =IFERROR((J30-I30)/ABS(I30),0) -> 0.0050098864 | M30: =IF(L30>=0,"🟢 On Track",IF(L30>=-0.1,"🟡 Watch","🔴 At Risk")) -> 🟢 On Track
A33: BUDGET vs FORECAST Q2 | H33: TARGET vs FORECAST Q2
A34: Based on actuals + forecasted months | H34: Based on actuals + forecasted months
A35: VERTICAL | B35: 2026 Budget | C35: Forecast | D35: $ Difference | E35: % Diff | F35: STATUS | H35: VERTICAL | I35: 2026 Target | J35: Forecast | K35: $ Difference | L35: % Diff | M35: STATUS
A36: Rotowire | B36: 2902566 | C36: =Forecast!E8+Forecast!F8+Forecast!G8 -> 3649065 | D36: =IFERROR(C36-B36,0) -> 746499 | E36: =IFERROR((C36-B36)/ABS(B36),0) -> 0.25718588 | F36: =IF(E36>=0,"🟢 On Track",IF(E36>=-0.1,"🟡 Watch","🔴 At Risk")) -> 🟢 On Track | H36: Rotowire | I36: 3068794 | J36: =C36 -> 3649065 | K36: =IFERROR(J36-I36,0) -> 580271.01 | L36: =IFERROR((J36-I36)/ABS(I36),0) -> 0.18908764 | M36: =IF(L36>=0,"🟢 On Track",IF(L36>=-0.1,"🟡 Watch","🔴 At Risk")) -> 🟢 On Track
A37: Bookies | B37: 1238076 | C37: =Forecast!E25+Forecast!F25+Forecast!G25 -> 837472 | D37: =IFERROR(C37-B37,0) -> -400604 | E37: =IFERROR((C37-B37)/ABS(B37),0) -> -0.3235698 | F37: =IF(E37>=0,"🟢 On Track",IF(E37>=-0.1,"🟡 Watch","🔴 At Risk")) -> 🔴 At Risk | H37: Bookies | I37: 1238076 | J37: =C37 -> 837472 | K37: =IFERROR(J37-I37,0) -> -400604 | L37: =IFERROR((J37-I37)/ABS(I37),0) -> -0.3235698 | M37: =IF(L37>=0,"🟢 On Track",IF(L37>=-0.1,"🟡 Watch","🔴 At Risk")) -> 🔴 At Risk
A38: Partnerships | B38: 249999 | C38: =Forecast!E28+Forecast!F28+Forecast!G28 -> 950000 | D38: =IFERROR(C38-B38,0) -> 700001 | E38: =IFERROR((C38-B38)/ABS(B38),0) -> 2.8000152 | F38: =IF(E38>=0,"🟢 On Track",IF(E38>=-0.1,"🟡 Watch","🔴 At Risk")) -> 🟢 On Track | H38: Partnerships | I38: 314500 | J38: =C38 -> 950000 | K38: =IFERROR(J38-I38,0) -> 635500 | L38: =IFERROR((J38-I38)/ABS(I38),0) -> 2.0206677 | M38: =IF(L38>=0,"🟢 On Track",IF(L38>=-0.1,"🟡 Watch","🔴 At Risk")) -> 🟢 On Track
A39: Local | B39: 570000 | C39: =Forecast!E57+Forecast!F57+Forecast!G57 -> 170800 | D39: =IFERROR(C39-B39,0) -> -399200 | E39: =IFERROR((C39-B39)/ABS(B39),0) -> -0.70035088 | F39: =IF(E39>=0,"🟢 On Track",IF(E39>=-0.1,"🟡 Watch","🔴 At Risk")) -> 🔴 At Risk | H39: Local | I39: 570000 | J39: =C39 -> 170800 | K39: =IFERROR(J39-I39,0) -> -399200 | L39: =IFERROR((J39-I39)/ABS(I39),0) -> -0.70035088 | M39: =IF(L39>=0,"🟢 On Track",IF(L39>=-0.1,"🟡 Watch","🔴 At Risk")) -> 🔴 At Risk
A40: OddsJam | B40: 5058106 | C40: =SUM(Forecast!E59:G61) -> 3884965 | D40: =IFERROR(C40-B40,0) -> -1173141 | E40: =IFERROR((C40-B40)/ABS(B40),0) -> -0.23193286 | F40: =IF(E40>=0,"🟢 On Track",IF(E40>=-0.1,"🟡 Watch","🔴 At Risk")) -> 🔴 At Risk | H40: OddsJam | I40: 4634834.5 | J40: =C40 -> 3884965 | K40: =IFERROR(J40-I40,0) -> -749869.48 | L40: =IFERROR((J40-I40)/ABS(I40),0) -> -0.16178992 | M40: =IF(L40>=0,"🟢 On Track",IF(L40>=-0.1,"🟡 Watch","🔴 At Risk")) -> 🔴 At Risk
A41: OpticOdds | B41: 5304568 | C41: =SUM(Forecast!E62:G63) -> 5339247 | D41: =IFERROR(C41-B41,0) -> 34679 | E41: =IFERROR((C41-B41)/ABS(B41),0) -> 0.0065375729 | F41: =IF(E41>=0,"🟢 On Track",IF(E41>=-0.1,"🟡 Watch","🔴 At Risk")) -> 🟢 On Track | H41: OpticOdds | I41: 5701053.1 | J41: =C41 -> 5339247 | K41: =IFERROR(J41-I41,0) -> -361806.08 | L41: =IFERROR((J41-I41)/ABS(I41),0) -> -0.063463026 | M41: =IF(L41>=0,"🟢 On Track",IF(L41>=-0.1,"🟡 Watch","🔴 At Risk")) -> 🟡 Watch
A42: TOTAL SDS | B42: =SUM(B36:B41) -> 15323315 | C42: =SUM(C36:C41) -> 14831549 | D42: =IFERROR(C42-B42,0) -> -491766 | E42: =IFERROR((C42-B42)/ABS(B42),0) -> -0.032092664 | F42: =IF(E42>=0,"🟢 On Track",IF(E42>=-0.1,"🟡 Watch","🔴 At Risk")) -> 🟡 Watch | H42: TOTAL SDS | I42: =SUM(I36:I41) -> 15527258 | J42: =SUM(J36:J41) -> 14831549 | K42: =IFERROR(J42-I42,0) -> -695708.55 | L42: =IFERROR((J42-I42)/ABS(I42),0) -> -0.04480563 | M42: =IF(L42>=0,"🟢 On Track",IF(L42>=-0.1,"🟡 Watch","🔴 At Risk")) -> 🟡 Watch
A45: BUDGET vs FORECAST Q3 | H45: TARGET vs FORECAST Q3
A46: Based on actuals + forecasted months | H46: Based on actuals + forecasted months
A47: VERTICAL | B47: 2026 Budget | C47: Forecast | D47: $ Difference | E47: % Diff | F47: STATUS | H47: VERTICAL | I47: 2026 Target | J47: Forecast | K47: $ Difference | L47: % Diff | M47: STATUS
A48: Rotowire | B48: 3827398 | C48: =Forecast!H8+Forecast!I8+Forecast!J8 -> 4763398 | D48: =IFERROR(C48-B48,0) -> 936000 | E48: =IFERROR((C48-B48)/ABS(B48),0) -> 0.24455257 | F48: =IF(E48>=0,"🟢 On Track",IF(E48>=-0.1,"🟡 Watch","🔴 At Risk")) -> 🟢 On Track | H48: Rotowire | I48: 4046590.5 | J48: =C48 -> 4763398 | K48: =IFERROR(J48-I48,0) -> 716807.5 | L48: =IFERROR((J48-I48)/ABS(I48),0) -> 0.17713863 | M48: =IF(L48>=0,"🟢 On Track",IF(L48>=-0.1,"🟡 Watch","🔴 At Risk")) -> 🟢 On Track
...

Sheet Forecast
A1: 2026 SDS Forecast
A2: VERTICAL / LINE | B2: Jan | C2: Feb | D2: Mar | E2: Apr | F2: May | G2: Jun | H2: Jul | I2: Aug | J2: Sep | K2: Oct | L2: Nov | M2: Dec | N2: FULL YEAR
A3: ROTOWIRE | B3: =IF(Rotowire!C4=0,"FORECAST","ACTUAL") -> ACTUAL | C3: =IF(Rotowire!D4=0,"FORECAST","ACTUAL") -> ACTUAL | D3: =IF(Rotowire!E4=0,"FORECAST","ACTUAL") -> ACTUAL | E3: =IF(Rotowire!F4=0,"FORECAST","ACTUAL") -> FORECAST | F3: =IF(Rotowire!G4=0,"FORECAST","ACTUAL") -> FORECAST | G3: =IF(Rotowire!H4=0,"FORECAST","ACTUAL") -> FORECAST | H3: =IF(Rotowire!I4=0,"FORECAST","ACTUAL") -> FORECAST | I3: =IF(Rotowire!J4=0,"FORECAST","ACTUAL") -> FORECAST | ... M3: =IF(Rotowire!N4=0,"FORECAST","ACTUAL") -> FORECAST
A4: B2C Subs | B4: =IF(Rotowire!C4=0,Rotowire!C6,Rotowire!C4) -> 474038.26 | C4: =IF(Rotowire!D4=0,Rotowire!D6,Rotowire!D4) -> 459134.72 | D4: =IF(Rotowire!E4=0,Rotowire!E6,Rotowire!E4) -> 552360.2 | E4: =IF(Rotowire!F4=0,Rotowire!F6,Rotowire!F4) -> 459073 | F4: =IF(Rotowire!G4=0,Rotowire!G6,Rotowire!G4) -> 452554 | G4: =IF(Rotowire!H4=0,Rotowire!H6,Rotowire!H4) -> 478438 | H4: =IF(Rotowire!I4=0,Rotowire!I6,Rotowire!I4) -> 491501 | I4: =IF(Rotowire!J4=0,Rotowire!J6,Rotowire!J4) -> 751620 | ... M4: =IF(Rotowire!N4=0,Rotowire!N6,Rotowire!N4) -> 681276 | N4: =SUM(B4:M4) -> 7030873.2
A5: Advertising | B5: =IF(Rotowire!C11=0,Rotowire!C13,Rotowire!C11) -> 111988.73 | C5: =IF(Rotowire!D11=0,Rotowire!D13,Rotowire!D11) -> 103856.8 | D5: =IF(Rotowire!E11=0,Rotowire!E13,Rotowire!E11) -> 134400.81 | E5: =IF(Rotowire!F11=0,Rotowire!F13,Rotowire!F11) -> 114000 | F5: =IF(Rotowire!G11=0,Rotowire!G13,Rotowire!G11) -> 79000 | G5: =IF(Rotowire!H11=0,Rotowire!H13,Rotowire!H11) -> 74000 | H5: =IF(Rotowire!I11=0,Rotowire!I13,Rotowire!I11) -> 82000 | I5: =IF(Rotowire!J11=0,Rotowire!J13,Rotowire!J11) -> 124000 | ... M5: =IF(Rotowire!N11=0,Rotowire!N13,Rotowire!N11) -> 124000 | N5: =SUM(B5:M5) -> 1302246.3
A6: B2B Content | B6: =IF(Rotowire!C18=0,Rotowire!C20,Rotowire!C18) -> 243987.32 | C6: =IF(Rotowire!D18=0,Rotowire!D20,Rotowire!D18) -> 236446.5 | D6: =IF(Rotowire!E18=0,Rotowire!E20,Rotowire!E18) -> 248430.63 | E6: =IF(Rotowire!F18=0,Rotowire!F20,Rotowire!F18) -> 254000 | F6: =IF(Rotowire!G18=0,Rotowire!G20,Rotowire!G18) -> 264000 | G6: =IF(Rotowire!H18=0,Rotowire!H20,Rotowire!H18) -> 274000 | H6: =IF(Rotowire!I18=0,Rotowire!I20,Rotowire!I18) -> 311000 | I6: =IF(Rotowire!J18=0,Rotowire!J20,Rotowire!J18) -> 321000 | ... M6: =IF(Rotowire!N18=0,Rotowire!N20,Rotowire!N18) -> 337000 | N6: =SUM(B6:M6) -> 3476864.5
A7: Rotowire Affiliate | B7: =IF(Bookies!C109=0,Bookies!C111,Bookies!C109) -> 373629.35 | C7: =IF(Bookies!D109=0,Bookies!D111,Bookies!D109) -> 478517.09 | D7: =IF(Bookies!E109=0,Bookies!E111,Bookies!E109) -> 568834.08 | E7: =IF(Bookies!F109=0,Bookies!F111,Bookies!F109) -> 500000 | F7: =IF(Bookies!G109=0,Bookies!G111,Bookies!G109) -> 350000 | G7: =IF(Bookies!H109=0,Bookies!H111,Bookies!H109) -> 350000 | H7: =IF(Bookies!I109=0,Bookies!I111,Bookies!I109) -> 350000 | I7: =IF(Bookies!J109=0,Bookies!J111,Bookies!J109) -> 500000 | ... M7: =IF(Bookies!N109=0,Bookies!N111,Bookies!N109) -> 500000 | N7: =SUM(B7:M7) -> 5570980.5
A8: SUBTOTAL — Rotowire | B8: =SUM(B4:B7) -> 1203643.7 | C8: =SUM(C4:C7) -> 1277955.1 | D8: =SUM(D4:D7) -> 1504025.7 | E8: =SUM(E4:E7) -> 1327073 | F8: =SUM(F4:F7) -> 1145554 | G8: =SUM(G4:G7) -> 1176438 | H8: =SUM(H4:H7) -> 1234501 | I8: =SUM(I4:I7) -> 1696620 | ... N8: =SUM(N4:N7) -> 17380964
A9: SPORTS AFFILIATE | B9: =IF(Bookies!C4=0,"FORECAST","ACTUAL") -> ACTUAL | C9: =IF(Bookies!D4=0,"FORECAST","ACTUAL") -> ACTUAL | D9: =IF(Bookies!E4=0,"FORECAST","ACTUAL") -> ACTUAL | E9: =IF(Bookies!F4=0,"FORECAST","ACTUAL") -> FORECAST | F9: =IF(Bookies!G4=0,"FORECAST","ACTUAL") -> FORECAST | G9: =IF(Bookies!H4=0,"FORECAST","ACTUAL") -> FORECAST | H9: =IF(Bookies!I4=0,"FORECAST","ACTUAL") -> FORECAST | I9: =IF(Bookies!J4=0,"FORECAST","ACTUAL") -> FORECAST | ... M9: =IF(Bookies!N4=0,"FORECAST","ACTUAL") -> FORECAST
A10: Bookies US | B10: =IF(Bookies!C4=0,Bookies!C6,Bookies!C4) -> -3260.2155 | C10: =IF(Bookies!D4=0,Bookies!D6,Bookies!D4) -> 44660 | D10: =IF(Bookies!E4=0,Bookies!E6,Bookies!E4) -> 2249 | E10: =IF(Bookies!F4=0,Bookies!F6,Bookies!F4) -> 55000 | F10: =IF(Bookies!G4=0,Bookies!G6,Bookies!G4) -> 55000 | G10: =IF(Bookies!H4=0,Bookies!H6,Bookies!H4) -> 55000 | H10: =IF(Bookies!I4=0,Bookies!I6,Bookies!I4) -> 95000 | I10: =IF(Bookies!J4=0,Bookies!J6,Bookies!J4) -> 105000 | ... M10: =IF(Bookies!N4=0,Bookies!N6,Bookies!N4) -> 105000 | N10: =SUM(B10:M10) -> 873648.78
A11: Bookies UK | B11: =IF(Bookies!C11=0,Bookies!C13,Bookies!C11) -> 212757.88 | C11: =IF(Bookies!D11=0,Bookies!D13,Bookies!D11) -> 148559.81 | D11: =IF(Bookies!E11=0,Bookies!E13,Bookies!E11) -> 9433 | E11: =IF(Bookies!F11=0,Bookies!F13,Bookies!F11) -> 150000 | F11: =IF(Bookies!G11=0,Bookies!G13,Bookies!G11) -> 150000 | G11: =IF(Bookies!H11=0,Bookies!H13,Bookies!H11) -> 150000 | H11: =IF(Bookies!I11=0,Bookies!I13,Bookies!I11) -> 150000 | I11: =IF(Bookies!J11=0,Bookies!J13,Bookies!J11) -> 215000 | ... M11: =IF(Bookies!N11=0,Bookies!N13,Bookies!N11) -> 200000 | N11: =SUM(B11:M11) -> 1990750.7
A12: Bookies IE | B12: =IF(Bookies!C18=0,Bookies!C20,Bookies!C18) -> 2024.5313 | C12: =IF(Bookies!D18=0,Bookies!D20,Bookies!D18) -> 6347.5797 | D12: =IF(Bookies!E18=0,Bookies!E20,Bookies!E18) -> 6358 | E12: =IF(Bookies!F18=0,Bookies!F20,Bookies!F18) -> 13500 | F12: =IF(Bookies!G18=0,Bookies!G20,Bookies!G18) -> 12000 | G12: =IF(Bookies!H18=0,Bookies!H20,Bookies!H18) -> 13500 | H12: =IF(Bookies!I18=0,Bookies!I20,Bookies!I18) -> 12000 | I12: =IF(Bookies!J18=0,Bookies!J20,Bookies!J18) -> 14000 | ... M12: =IF(Bookies!N18=0,Bookies!N20,Bookies!N18) -> 10000 | N12: =SUM(B12:M12) -> 125730.11
A13: Bookies IN | B13: =IF(Bookies!C25=0,Bookies!C27,Bookies!C25) -> 5566.1161 | C13: =IF(Bookies!D25=0,Bookies!D27,Bookies!D25) -> 14370.106 | D13: =IF(Bookies!E25=0,Bookies!E27,Bookies!E25) -> 7935 | E13: =IF(Bookies!F25=0,Bookies!F27,Bookies!F25) -> 8000 | F13: =IF(Bookies!G25=0,Bookies!G27,Bookies!G25) -> 8000 | G13: =IF(Bookies!H25=0,Bookies!H27,Bookies!H25) -> 8000 | H13: =IF(Bookies!I25=0,Bookies!I27,Bookies!I25) -> 8000 | I13: =IF(Bookies!J25=0,Bookies!J27,Bookies!J25) -> 8000 | ... M13: =IF(Bookies!N25=0,Bookies!N27,Bookies!N25) -> 8000 | N13: =SUM(B13:M13) -> 99871.222
A14: Bookies CA | B14: =IF(Bookies!C32=0,Bookies!C34,Bookies!C32) -> 9408.0531 | C14: =IF(Bookies!D32=0,Bookies!D34,Bookies!D32) -> 4565.4974 | D14: =IF(Bookies!E32=0,Bookies!E34,Bookies!E32) -> 14841 | E14: =IF(Bookies!F32=0,Bookies!F34,Bookies!F32) -> 14500 | F14: =IF(Bookies!G32=0,Bookies!G34,Bookies!G32) -> 14500 | G14: =IF(Bookies!H32=0,Bookies!H34,Bookies!H32) -> 15000 | H14: =IF(Bookies!I32=0,Bookies!I34,Bookies!I32) -> 16500 | I14: =IF(Bookies!J32=0,Bookies!J34,Bookies!J32) -> 16500 | ... M14: =IF(Bookies!N32=0,Bookies!N34,Bookies!N32) -> 18000 | N14: =SUM(B14:M14) -> 180314.55
A15: Bookies AU | B15: =IF(Bookies!C39=0,Bookies!C41,Bookies!C39) -> 2960.88 | C15: =IF(Bookies!D39=0,Bookies!D41,Bookies!D39) -> 687.37603 | D15: =IF(Bookies!E39=0,Bookies!E41,Bookies!E39) -> -1533 | E15: =IF(Bookies!F39=0,Bookies!F41,Bookies!F39) -> 1500 | F15: =IF(Bookies!G39=0,Bookies!G41,Bookies!G39) -> 1500 | G15: =IF(Bookies!H39=0,Bookies!H41,Bookies!H39) -> 1500 | H15: =IF(Bookies!I39=0,Bookies!I41,Bookies!I39) -> 1500 | I15: =IF(Bookies!J39=0,Bookies!J41,Bookies!J39) -> 1500 | ... M15: =IF(Bookies!N39=0,Bookies!N41,Bookies!N39) -> 1500 | N15: =SUM(B15:M15) -> 15615.256
A16: Bookies NZ | B16: =IF(Bookies!C46=0,Bookies!C48,Bookies!C46) -> 1721.4416 | C16: =IF(Bookies!D46=0,Bookies!D48,Bookies!D46) -> 4112.945 | D16: =IF(Bookies!E46=0,Bookies!E48,Bookies!E46) -> 4550 | E16: =IF(Bookies!F46=0,Bookies!F48,Bookies!F46) -> 7500 | F16: =IF(Bookies!G46=0,Bookies!G48,Bookies!G46) -> 8000 | G16: =IF(Bookies!H46=0,Bookies!H48,Bookies!H46) -> 8000 | H16: =IF(Bookies!I46=0,Bookies!I48,Bookies!I46) -> 8500 | I16: =IF(Bookies!J46=0,Bookies!J48,Bookies!J46) -> 8500 | ... M16: =IF(Bookies!N46=0,Bookies!N48,Bookies!N46) -> 8500 | N16: =SUM(B16:M16) -> 86884.387
A17: Bookies MX | B17: =IF(Bookies!C53=0,Bookies!C55,Bookies!C53) -> 8337.3099 | C17: =IF(Bookies!D53=0,Bookies!D55,Bookies!D53) -> 3992.0958 | D17: =IF(Bookies!E53=0,Bookies!E55,Bookies!E53) -> 1794 | E17: =IF(Bookies!F53=0,Bookies!F55,Bookies!F53) -> 5500 | F17: =IF(Bookies!G53=0,Bookies!G55,Bookies!G53) -> 5500 | G17: =IF(Bookies!H53=0,Bookies!H55,Bookies!H53) -> 5500 | H17: =IF(Bookies!I53=0,Bookies!I55,Bookies!I53) -> 5500 | I17: =IF(Bookies!J53=0,Bookies!J55,Bookies!J53) -> 5500 | ... M17: =IF(Bookies!N53=0,Bookies!N55,Bookies!N53) -> 5500 | N17: =SUM(B17:M17) -> 63623.406
A18: Bookies NG | B18: =IF(Bookies!C60=0,Bookies!C62,Bookies!C60) -> 0.648964 | C18: =IF(Bookies!D60=0,Bookies!D62,Bookies!D60) -> 0 | D18: =IF(Bookies!E60=0,Bookies!E62,Bookies!E60) -> 0 | E18: =IF(Bookies!F60=0,Bookies!F62,Bookies!F60) -> 0 | F18: =IF(Bookies!G60=0,Bookies!G62,Bookies!G60) -> 0 | G18: =IF(Bookies!H60=0,Bookies!H62,Bookies!H60) -> 0 | H18: =IF(Bookies!I60=0,Bookies!I62,Bookies!I60) -> 0 | I18: =IF(Bookies!J60=0,Bookies!J62,Bookies!J60) -> 0 | ... M18: =IF(Bookies!N60=0,Bookies!N62,Bookies!N60) -> 0 | N18: =SUM(B18:M18) -> 0.648964
A19: Bookies NL | B19: =IF(Bookies!C67=0,Bookies!C69,Bookies!C67) -> 601.71932 | C19: =IF(Bookies!D67=0,Bookies!D69,Bookies!D67) -> 224.09292 | D19: =IF(Bookies!E67=0,Bookies!E69,Bookies!E67) -> 15 | E19: =IF(Bookies!F67=0,Bookies!F69,Bookies!F67) -> 1500 | F19: =IF(Bookies!G67=0,Bookies!G69,Bookies!G67) -> 1500 | G19: =IF(Bookies!H67=0,Bookies!H69,Bookies!H67) -> 1500 | H19: =IF(Bookies!I67=0,Bookies!I69,Bookies!I67) -> 1500 | I19: =IF(Bookies!J67=0,Bookies!J69,Bookies!J67) -> 1500 | ... M19: =IF(Bookies!N67=0,Bookies!N69,Bookies!N67) -> 1500 | N19: =SUM(B19:M19) -> 14340.812
A20: Bookies BR | B20: =IF(Bookies!C74=0,Bookies!C76,Bookies!C74) -> 111.69258 | C20: =IF(Bookies!D74=0,Bookies!D76,Bookies!D74) -> 260.21518 | D20: =IF(Bookies!E74=0,Bookies!E76,Bookies!E74) -> -77 | E20: =IF(Bookies!F74=0,Bookies!F76,Bookies!F74) -> 100 | F20: =IF(Bookies!G74=0,Bookies!G76,Bookies!G74) -> 100 | G20: =IF(Bookies!H74=0,Bookies!H76,Bookies!H74) -> 100 | H20: =IF(Bookies!I74=0,Bookies!I76,Bookies!I74) -> 100 | I20: =IF(Bookies!J74=0,Bookies!J76,Bookies!J74) -> 100 | ... M20: =IF(Bookies!N74=0,Bookies!N76,Bookies!N74) -> 100 | N20: =SUM(B20:M20) -> 1194.9078
A21: Bookies GX | B21: =IF(Bookies!C81=0,Bookies!C83,Bookies!C81) -> 167.97545 | C21: =IF(Bookies!D81=0,Bookies!D83,Bookies!D81) -> 546 | D21: =IF(Bookies!E81=0,Bookies!E83,Bookies!E81) -> 651 | E21: =IF(Bookies!F81=0,Bookies!F83,Bookies!F81) -> 100 | F21: =IF(Bookies!G81=0,Bookies!G83,Bookies!G81) -> 100 | G21: =IF(Bookies!H81=0,Bookies!H83,Bookies!H81) -> 100 | H21: =IF(Bookies!I81=0,Bookies!I83,Bookies!I81) -> 100 | I21: =IF(Bookies!J81=0,Bookies!J83,Bookies!J81) -> 100 | ... M21: =IF(Bookies!N81=0,Bookies!N83,Bookies!N81) -> 100 | N21: =SUM(B21:M21) -> 2264.9755
A22: Bookies ES | B22: =IF(Bookies!C88=0,Bookies!C90,Bookies!C88) -> 100 | C22: =IF(Bookies!D88=0,Bookies!D90,Bookies!D88) -> 5.797546 | D22: =IF(Bookies!E88=0,Bookies!E90,Bookies!E88) -> 289 | E22: =IF(Bookies!F88=0,Bookies!F90,Bookies!F88) -> 500 | F22: =IF(Bookies!G88=0,Bookies!G90,Bookies!G88) -> 500 | G22: =IF(Bookies!H88=0,Bookies!H90,Bookies!H88) -> 500 | H22: =IF(Bookies!I88=0,Bookies!I90,Bookies!I88) -> 1000 | I22: =IF(Bookies!J88=0,Bookies!J90,Bookies!J88) -> 1000 | ... M22: =IF(Bookies!N88=0,Bookies!N90,Bookies!N88) -> 1000 | N22: =SUM(B22:M22) -> 7894.7975
A23: Bookmakers | B23: =IF(Bookies!C95=0,Bookies!C97,Bookies!C95) -> -13263.989 | C23: =IF(Bookies!D95=0,Bookies!D97,Bookies!D95) -> 17347.598 | D23: =IF(Bookies!E95=0,Bookies!E97,Bookies!E95) -> 14186 | E23: =IF(Bookies!F95=0,Bookies!F97,Bookies!F95) -> 12500 | F23: =IF(Bookies!G95=0,Bookies!G97,Bookies!G95) -> 12500 | G23: =IF(Bookies!H95=0,Bookies!H97,Bookies!H95) -> 12500 | H23: =IF(Bookies!I95=0,Bookies!I97,Bookies!I95) -> 12500 | I23: =IF(Bookies!J95=0,Bookies!J97,Bookies!J95) -> 12500 | ... M23: =IF(Bookies!N95=0,Bookies!N97,Bookies!N95) -> 12500 | N23: =SUM(B23:M23) -> 130769.61
A24: BetSync | B24: =IF(Bookies!C102=0,Bookies!C104,Bookies!C102) -> 0 | C24: =IF(Bookies!D102=0,Bookies!D104,Bookies!D102) -> 1498 | D24: =IF(Bookies!E102=0,Bookies!E104,Bookies!E102) -> 5273 | E24: =IF(Bookies!F102=0,Bookies!F104,Bookies!F102) -> 7382 | F24: =IF(Bookies!G102=0,Bookies!G104,Bookies!G102) -> 8859 | G24: =IF(Bookies!H102=0,Bookies!H104,Bookies!H102) -> 10631 | H24: =IF(Bookies!I102=0,Bookies!I104,Bookies!I102) -> 11694 | I24: =IF(Bookies!J102=0,Bookies!J104,Bookies!J102) -> 14032 | ... N24: =IF(Bookies!O102=0,Bookies!O104,Bookies!O102) -> 6771
A25: SUBTOTAL — Sports Affiliate | B25: =SUM(B10:B24) -> 227234.04 | C25: =SUM(C10:C24) -> 247177.11 | D25: =SUM(D10:D24) -> 65964 | E25: =SUM(E10:E24) -> 277582 | F25: =SUM(F10:F24) -> 278059 | G25: =SUM(G10:G24) -> 281831 | H25: =SUM(H10:H24) -> 323894 | I25: =SUM(I10:I24) -> 403232 | ... M25: =SUM(M10:M24) -> 400797 | N25: =SUM(B25:M25) -> 3742664.2
A26: PARTNERSHIPS | B26: =IF(Partnerships!C4=0,"FORECAST","ACTUAL") -> ACTUAL | C26: =IF(Partnerships!D4=0,"FORECAST","ACTUAL") -> ACTUAL | D26: =IF(Partnerships!E4=0,"FORECAST","ACTUAL") -> ACTUAL | E26: =IF(Partnerships!F4=0,"FORECAST","ACTUAL") -> FORECAST | F26: =IF(Partnerships!G4=0,"FORECAST","ACTUAL") -> FORECAST | G26: =IF(Partnerships!H4=0,"FORECAST","ACTUAL") -> FORECAST | H26: =IF(Partnerships!I4=0,"FORECAST","ACTUAL") -> FORECAST | I26: =IF(Partnerships!J4=0,"FORECAST","ACTUAL") -> FORECAST | ... M26: =IF(Partnerships!N4=0,"FORECAST","ACTUAL") -> FORECAST
A27: GAN Affiliate | B27: =IF(Partnerships!C4=0,Partnerships!C6,Partnerships!C4) -> 618795.88 | C27: =IF(Partnerships!D4=0,Partnerships!D6,Partnerships!D4) -> 746747.75 | D27: =IF(Partnerships!E4=0,Partnerships!E6,Partnerships!E4) -> 496449.58 | E27: =IF(Partnerships!F4=0,Partnerships!F6,Partnerships!F4) -> 350000 | F27: =IF(Partnerships!G4=0,Partnerships!G6,Partnerships!G4) -> 300000 | G27: =IF(Partnerships!H4=0,Partnerships!H6,Partnerships!H4) -> 300000 | H27: =IF(Partnerships!I4=0,Partnerships!I6,Partnerships!I4) -> 300000 | I27: =IF(Partnerships!J4=0,Partnerships!J6,Partnerships!J4) -> 400000 | ... M27: =IF(Partnerships!N4=0,Partnerships!N6,Partnerships!N4) -> 500000 | N27: =SUM(B27:M27) -> 5611993.2
A28: SUBTOTAL — Partnerships | B28: =SUM(B27:B27) -> 618795.88 | C28: =SUM(C27:C27) -> 746747.75 | D28: =SUM(D27:D27) -> 496449.58 | E28: =SUM(E27:E27) -> 350000 | F28: =SUM(F27:F27) -> 300000 | G28: =SUM(G27:G27) -> 300000 | H28: =SUM(H27:H27) -> 300000 | I28: =SUM(I27:I27) -> 400000 | ... M28: =SUM(M27:M27) -> 500000 | N28: =SUM(B28:M28) -> 5611993.2
A29: LOCAL | B29: =IF(Local!C4=0,"FORECAST","ACTUAL") -> ACTUAL | C29: =IF(Local!D4=0,"FORECAST","ACTUAL") -> ACTUAL | D29: =IF(Local!E4=0,"FORECAST","ACTUAL") -> ACTUAL | E29: =IF(Local!F4=0,"FORECAST","ACTUAL") -> FORECAST | F29: =IF(Local!G4=0,"FORECAST","ACTUAL") -> FORECAST | G29: =IF(Local!H4=0,"FORECAST","ACTUAL") -> FORECAST | H29: =IF(Local!I4=0,"FORECAST","ACTUAL") -> FORECAST | I29: =IF(Local!J4=0,"FORECAST","ACTUAL") -> FORECAST | ... M29: =IF(Local!N4=0,"FORECAST","ACTUAL") -> FORECAST
A30: BetArizona | B30: =IF(Local!C4=0,Local!C6,Local!C4) -> 13350.067 | C30: =IF(Local!D4=0,Local!D6,Local!D4) -> 8927.3897 | D30: =IF(Local!E4=0,Local!E6,Local!E4) -> 15835.692 | E30: =IF(Local!F4=0,Local!F6,Local!F4) -> 5000 | F30: =IF(Local!G4=0,Local!G6,Local!G4) -> 3000 | G30: =IF(Local!H4=0,Local!H6,Local!H4) -> 3000 | H30: =IF(Local!I4=0,Local!I6,Local!I4) -> 3000 | I30: =IF(Local!J4=0,Local!J6,Local!J4) -> 5000 | ... M30: =IF(Local!N4=0,Local!N6,Local!N4) -> 15000 | N30: =SUM(B30:M30) -> 122113.15
A31: BetVirginia | B31: =IF(Local!C11=0,Local!C13,Local!C11) -> 10130.181 | C31: =IF(Local!D11=0,Local!D13,Local!D11) -> 2170.761 | D31: =IF(Local!E11=0,Local!E13,Local!E11) -> 4496.6503 | E31: =IF(Local!F11=0,Local!F13,Local!F11) -> 8000 | F31: =IF(Local!G11=0,Local!G13,Local!G11) -> 3000 | G31: =IF(Local!H11=0,Local!H13,Local!H11) -> 3000 | H31: =IF(Local!I11=0,Local!I13,Local!I11) -> 3000 | I31: =IF(Local!J11=0,Local!J13,Local!J11) -> 5000 | ... M31: =IF(Local!N11=0,Local!N13,Local!N11) -> 10000 | N31: =SUM(B31:M31) -> 74797.592
A32: BetKansas | B32: =IF(Local!C18=0,Local!C20,Local!C18) -> -9.983818 | C32: =IF(Local!D18=0,Local!D20,Local!D18) -> 14220.312 | D32: =IF(Local!E18=0,Local!E20,Local!E18) -> 9727.514 | E32: =IF(Local!F18=0,Local!F20,Local!F18) -> 2000 | F32: =IF(Local!G18=0,Local!G20,Local!G18) -> 1000 | G32: =IF(Local!H18=0,Local!H20,Local!H18) -> 1000 | H32: =IF(Local!I18=0,Local!I20,Local!I18) -> 1000 | I32: =IF(Local!J18=0,Local!J20,Local!J18) -> 5000 | ... M32: =IF(Local!N18=0,Local!N20,Local!N18) -> 15000 | N32: =SUM(B32:M32) -> 83937.842
A33: BetOhio | B33: =IF(Local!C25=0,Local!C27,Local!C25) -> 4945.2445 | C33: =IF(Local!D25=0,Local!D27,Local!D25) -> 2880.0743 | D33: =IF(Local!E25=0,Local!E27,Local!E25) -> 8564.9448 | E33: =IF(Local!F25=0,Local!F27,Local!F25) -> 2000 | F33: =IF(Local!G25=0,Local!G27,Local!G25) -> 1000 | G33: =IF(Local!H25=0,Local!H27,Local!H25) -> 1000 | H33: =IF(Local!I25=0,Local!I27,Local!I25) -> 1000 | I33: =IF(Local!J25=0,Local!J27,Local!J25) -> 3000 | ... M33: =IF(Local!N25=0,Local!N27,Local!N25) -> 10000 | N33: =SUM(B33:M33) -> 60390.264
A34: BetKentucky | B34: =IF(Local!C32=0,Local!C34,Local!C32) -> 2176.933 | C34: =IF(Local!D32=0,Local!D34,Local!D32) -> 1425.0822 | D34: =IF(Local!E32=0,Local!E34,Local!E32) -> 3628.2569 | E34: =IF(Local!F32=0,Local!F34,Local!F32) -> 2000 | F34: =IF(Local!G32=0,Local!G34,Local!G32) -> 1000 | G34: =IF(Local!H32=0,Local!H34,Local!H32) -> 1000 | H34: =IF(Local!I32=0,Local!I34,Local!I32) -> 1000 | I34: =IF(Local!J32=0,Local!J34,Local!J32) -> 3000 | ... M34: =IF(Local!N32=0,Local!N34,Local!N32) -> 5000 | N34: =SUM(B34:M34) -> 33230.272
A35: BetMassachusetts | B35: =IF(Local!C39=0,Local!C41,Local!C39) -> 7974.6974 | C35: =IF(Local!D39=0,Local!D41,Local!D39) -> 6956.5644 | D35: =IF(Local!E39=0,Local!E41,Local!E39) -> 2045.0664 | E35: =IF(Local!F39=0,Local!F41,Local!F39) -> 8000 | F35: =IF(Local!G39=0,Local!G41,Local!G39) -> 3000 | G35: =IF(Local!H39=0,Local!H41,Local!H39) -> 3000 | H35: =IF(Local!I39=0,Local!I41,Local!I39) -> 3000 | I35: =IF(Local!J39=0,Local!J41,Local!J39) -> 5000 | ... M35: =IF(Local!N39=0,Local!N41,Local!N39) -> 10000 | N35: =SUM(B35:M35) -> 74976.328
A36: BetTennessee | B36: =IF(Local!C46=0,Local!C48,Local!C46) -> 1911.806 | C36: =IF(Local!D46=0,Local!D48,Local!D46) -> -363.29582 | D36: =IF(Local!E46=0,Local!E48,Local!E46) -> 2161.5845 | E36: =IF(Local!F46=0,Local!F48,Local!F46) -> 2000 | F36: =IF(Local!G46=0,Local!G48,Local!G46) -> 1000 | G36: =IF(Local!H46=0,Local!H48,Local!H46) -> 1000 | H36: =IF(Local!I46=0,Local!I48,Local!I46) -> 1000 | I36: =IF(Local!J46=0,Local!J48,Local!J46) -> 3000 | ... M36: =IF(Local!N46=0,Local!N48,Local!N46) -> 5000 | N36: =SUM(B36:M36) -> 29710.095
A37: LouisianaBets | B37: =IF(Local!C53=0,Local!C55,Local!C53) -> -376.13058 | C37: =IF(Local!D53=0,Local!D55,Local!D53) -> -1212.1453 | D37: =IF(Local!E53=0,Local!E55,Local!E53) -> 1384.8506 | E37: =IF(Local!F53=0,Local!F55,Local!F53) -> 1000 | F37: =IF(Local!G53=0,Local!G55,Local!G53) -> 1000 | G37: =IF(Local!H53=0,Local!H55,Local!H53) -> 1000 | H37: =IF(Local!I53=0,Local!I55,Local!I53) -> 1000 | I37: =IF(Local!J53=0,Local!J55,Local!J53) -> 1000 | ... M37: =IF(Local!N53=0,Local!N55,Local!N53) -> 1000 | N37: =SUM(B37:M37) -> 8796.5747
A38: BetColorado | B38: =IF(Local!C60=0,Local!C62,Local!C60) -> 1756.431 | C38: =IF(Local!D60=0,Local!D62,Local!D60) -> 7497.8106 | D38: =IF(Local!E60=0,Local!E62,Local!E60) -> 1043.8384 | E38: =IF(Local!F60=0,Local!F62,Local!F60) -> 2000 | F38: =IF(Local!G60=0,Local!G62,Local!G60) -> 1000 | G38: =IF(Local!H60=0,Local!H62,Local!H60) -> 1000 | H38: =IF(Local!I60=0,Local!I62,Local!I60) -> 1000 | I38: =IF(Local!J60=0,Local!J62,Local!J60) -> 3000 | ... M38: =IF(Local!N60=0,Local!N62,Local!N60) -> 5000 | N38: =SUM(B38:M38) -> 36298.08
A39: IndianaBets | B39: =IF(Local!C67=0,Local!C69,Local!C67) -> 2.894005 | C39: =IF(Local!D67=0,Local!D69,Local!D67) -> 42.601367 | D39: =IF(Local!E67=0,Local!E69,Local!E67) -> 39.869312 | E39: =IF(Local!F67=0,Local!F69,Local!F67) -> 0 | F39: =IF(Local!G67=0,Local!G69,Local!G67) -> 0 | G39: =IF(Local!H67=0,Local!H69,Local!H67) -> 0 | H39: =IF(Local!I67=0,Local!I69,Local!I67) -> 0 | I39: =IF(Local!J67=0,Local!J69,Local!J67) -> 0 | ... M39: =IF(Local!N67=0,Local!N69,Local!N67) -> 0 | N39: =SUM(B39:M39) -> 85.364684
A40: IowaBets | B40: =IF(Local!C74=0,Local!C76,Local!C74) -> 84.286657 | C40: =IF(Local!D74=0,Local!D76,Local!D74) -> 268.81932 | D40: =IF(Local!E74=0,Local!E76,Local!E74) -> -18.937923 | E40: =IF(Local!F74=0,Local!F76,Local!F74) -> 100 | F40: =IF(Local!G74=0,Local!G76,Local!G74) -> 100 | G40: =IF(Local!H74=0,Local!H76,Local!H74) -> 100 | H40: =IF(Local!I74=0,Local!I76,Local!I74) -> 100 | I40: =IF(Local!J74=0,Local!J76,Local!J74) -> 100 | ... M40: =IF(Local!N74=0,Local!N76,Local!N74) -> 100 | N40: =SUM(B40:M40) -> 1234.1681
...

Sheet Rotowire
A1: Rotowire — 2026 Revenue Detail
A2: Read-only · All data flows from Forecast Input tab · Do not type here
A3: SUB-LINE | B3: METRIC | C3: Jan | D3: Feb | E3: Mar | F3: Apr | G3: May | H3: Jun | I3: Jul | J3: Aug | K3: Sep | L3: Oct | M3: Nov | N3: Dec | O3: FULL YEAR
A4: B2C Subs | B4: Actual 26' | C4: ='Forecast Input'!D5 -> 474038.26 | D4: ='Forecast Input'!E5 -> 459134.72 | E4: ='Forecast Input'!F5 -> 552360.2 | F4: ='Forecast Input'!G5 -> 0 | G4: ='Forecast Input'!H5 -> 0 | H4: ='Forecast Input'!I5 -> 0 | I4: ='Forecast Input'!J5 -> 0 | J4: ='Forecast Input'!K5 -> 0 | ... N4: ='Forecast Input'!O5 -> 0 | O4: =SUM(C4:N4) -> 1485533.2
B5: Actual 25' | C5: 475949 | D5: 440366 | E5: 525216 | F5: 453059 | G5: 413871 | H5: 403322 | I5: 413273 | J5: 487182 | K5: 584970 | L5: 525388 | M5: 499582 | N5: 576723 | O5: =SUM(C5:N5) -> 5798901
B6: Forecast | C6: ='Forecast Input'!D6 -> 484326 | D6: ='Forecast Input'!E6 -> 443408 | E6: ='Forecast Input'!F6 -> 531544 | F6: ='Forecast Input'!G6 -> 459073 | G6: ='Forecast Input'!H6 -> 452554 | H6: ='Forecast Input'!I6 -> 478438 | I6: ='Forecast Input'!J6 -> 491501 | J6: ='Forecast Input'!K6 -> 751620 | ... N6: ='Forecast Input'!O6 -> 681276 | O6: =SUM(C6:N6) -> 7004618 | P6: NOTES PLACED IN NEXT TAB
B7: Actual vs Forecast $ | C7: =IF(C4=0,"-",C4-C6) -> -10287.736 | D7: =IF(D4=0,"-",D4-D6) -> 15726.718 | E7: =IF(E4=0,"-",E4-E6) -> 20816.196 | F7: =IF(F4=0,"-",F4-F6) -> - | G7: =IF(G4=0,"-",G4-G6) -> - | H7: =IF(H4=0,"-",H4-H6) -> - | I7: =IF(I4=0,"-",I4-I6) -> - | J7: =IF(J4=0,"-",J4-J6) -> - | ... N7: =IF(N4=0,"-",N4-N6) -> -
B8: Actual vs Forecast % | C8: =IFERROR(C7/C4,"-") -> -0.021702332 | D8: =IFERROR(D7/D4,"-") -> 0.034252948 | E8: =IFERROR(E7/E4,"-") -> 0.037685909 | F8: =IFERROR(F7/F4,"-") -> - | G8: =IFERROR(G7/G4,"-") -> - | H8: =IFERROR(H7/H4,"-") -> - | I8: =IFERROR(I7/I4,"-") -> - | J8: =IFERROR(J7/J4,"-") -> - | ... N8: =IFERROR(N7/N4,"-") -> -
B9: Forecast vs PY $ | C9: =IFERROR(C6-C5,"-") -> 8377 | D9: =IFERROR(D6-D5,"-") -> 3042 | E9: =IFERROR(E6-E5,"-") -> 6328 | F9: =IFERROR(F6-F5,"-") -> 6014 | G9: =IFERROR(G6-G5,"-") -> 38683 | H9: =IFERROR(H6-H5,"-") -> 75116 | I9: =IFERROR(I6-I5,"-") -> 78228 | J9: =IFERROR(J6-J5,"-") -> 264438 | ... N9: =IFERROR(N6-N5,"-") -> 104553
B10: Forecast vs PY % | C10: =IFERROR(C9/C5,"-") -> 0.017600625 | D10: =IFERROR(D9/D5,"-") -> 0.0069078903 | E10: =IFERROR(E9/E5,"-") -> 0.012048376 | F10: =IFERROR(F9/F5,"-") -> 0.013274209 | G10: =IFERROR(G9/G5,"-") -> 0.093466322 | H10: =IFERROR(H9/H5,"-") -> 0.18624325 | I10: =IFERROR(I9/I5,"-") -> 0.18928892 | J10: =IFERROR(J9/J5,"-") -> 0.54279099 | ... N10: =IFERROR(N9/N5,"-") -> 0.18128807
A11: Advertising | B11: Actual 26' | C11: ='Forecast Input'!D7 -> 111988.73 | D11: ='Forecast Input'!E7 -> 103856.8 | E11: ='Forecast Input'!F7 -> 134400.81 | F11: ='Forecast Input'!G7 -> 0 | G11: ='Forecast Input'!H7 -> 0 | H11: ='Forecast Input'!I7 -> 0 | I11: ='Forecast Input'!J7 -> 0 | J11: ='Forecast Input'!K7 -> 0 | ... N11: ='Forecast Input'!O7 -> 0 | O11: =SUM(C11:N11) -> 350246.34
B12: Actual 25' | C12: 59518 | D12: 59327 | E12: 106033 | F12: 131901 | G12: 65346 | H12: 90721 | I12: 112099 | J12: 111648 | K12: 100884 | L12: 121514 | M12: 180968 | N12: 122875 | O12: =SUM(C12:N12) -> 1262834
B13: Forecast | C13: ='Forecast Input'!D8 -> 73000 | D13: ='Forecast Input'!E8 -> 79000 | E13: ='Forecast Input'!F8 -> 115000 | F13: ='Forecast Input'!G8 -> 114000 | G13: ='Forecast Input'!H8 -> 79000 | H13: ='Forecast Input'!I8 -> 74000 | I13: ='Forecast Input'!J8 -> 82000 | J13: ='Forecast Input'!K8 -> 124000 | ... N13: ='Forecast Input'!O8 -> 124000 | O13: =SUM(C13:N13) -> 1219000
B14: Actual vs Forecast $ | C14: =IF(C11=0,"-",C11-C13) -> 38988.725 | D14: =IF(D11=0,"-",D11-D13) -> 24856.796 | E14: =IF(E11=0,"-",E11-E13) -> 19400.815 | F14: =IF(F11=0,"-",F11-F13) -> - | G14: =IF(G11=0,"-",G11-G13) -> - | H14: =IF(H11=0,"-",H11-H13) -> - | I14: =IF(I11=0,"-",I11-I13) -> - | J14: =IF(J11=0,"-",J11-J13) -> - | ... N14: =IF(N11=0,"-",N11-N13) -> -
B15: Actual vs Forecast % | C15: =IFERROR(C14/C11,"-") -> 0.34814866 | D15: =IFERROR(D14/D11,"-") -> 0.23933721 | E15: =IFERROR(E14/E11,"-") -> 0.14435042 | F15: =IFERROR(F14/F11,"-") -> - | G15: =IFERROR(G14/G11,"-") -> - | H15: =IFERROR(H14/H11,"-") -> - | I15: =IFERROR(I14/I11,"-") -> - | J15: =IFERROR(J14/J11,"-") -> - | ... N15: =IFERROR(N14/N11,"-") -> -
B16: Forecast vs PY $ | C16: =IFERROR(C13-C12,"-") -> 13482 | D16: =IFERROR(D13-D12,"-") -> 19673 | E16: =IFERROR(E13-E12,"-") -> 8967 | F16: =IFERROR(F13-F12,"-") -> -17901 | G16: =IFERROR(G13-G12,"-") -> 13654 | H16: =IFERROR(H13-H12,"-") -> -16721 | I16: =IFERROR(I13-I12,"-") -> -30099 | J16: =IFERROR(J13-J12,"-") -> 12352 | ... N16: =IFERROR(N13-N12,"-") -> 1125
B17: Forecast vs PY % | C17: =IFERROR(C16/C12,"-") -> 0.22651971 | D17: =IFERROR(D16/D12,"-") -> 0.33160281 | E17: =IFERROR(E16/E12,"-") -> 0.084568012 | F17: =IFERROR(F16/F12,"-") -> -0.13571542 | G17: =IFERROR(G16/G12,"-") -> 0.20894929 | H17: =IFERROR(H16/H12,"-") -> -0.18431234 | I17: =IFERROR(I16/I12,"-") -> -0.26850373 | J17: =IFERROR(J16/J12,"-") -> 0.11063342 | ... N17: =IFERROR(N16/N12,"-") -> 0.009155646
A18: B2B Content | B18: Actual 26' | C18: ='Forecast Input'!D9 -> 243987.32 | D18: ='Forecast Input'!E9 -> 236446.5 | E18: ='Forecast Input'!F9 -> 248430.63 | F18: ='Forecast Input'!G9 -> 0 | G18: ='Forecast Input'!H9 -> 0 | H18: ='Forecast Input'!I9 -> 0 | I18: ='Forecast Input'!J9 -> 0 | J18: ='Forecast Input'!K9 -> 0 | ... N18: ='Forecast Input'!O9 -> 0 | O18: =SUM(C18:N18) -> 728864.45
B19: Actual 25' | C19: 281596 | D19: 256251 | E19: 254563 | F19: 288186 | G19: 266344 | H19: 268658 | I19: 257179 | J19: 258775 | K19: 270002 | L19: 258897 | M19: 264648 | N19: 264986 | O19: =SUM(C19:N19) -> 3190085
B20: Forecast | C20: ='Forecast Input'!D10 -> 273000 | D20: ='Forecast Input'!E10 -> 259000 | E20: ='Forecast Input'!F10 -> 248000 | F20: ='Forecast Input'!G10 -> 254000 | G20: ='Forecast Input'!H10 -> 264000 | H20: ='Forecast Input'!I10 -> 274000 | I20: ='Forecast Input'!J10 -> 311000 | J20: ='Forecast Input'!K10 -> 321000 | ... N20: ='Forecast Input'!O10 -> 337000 | O20: =SUM(C20:N20) -> 3528000
B21: Actual vs Forecast $ | C21: =IF(C18=0,"-",C18-C20) -> -29012.682 | D21: =IF(D18=0,"-",D18-D20) -> -22553.5 | E21: =IF(E18=0,"-",E18-E20) -> 430.63376 | F21: =IF(F18=0,"-",F18-F20) -> - | G21: =IF(G18=0,"-",G18-G20) -> - | H21: =IF(H18=0,"-",H18-H20) -> - | I21: =IF(I18=0,"-",I18-I20) -> - | J21: =IF(J18=0,"-",J18-J20) -> - | ... N21: =IF(N18=0,"-",N18-N20) -> -
B22: Actual vs Forecast % | C22: =IFERROR(C21/C18,"-") -> -0.11891062 | D22: =IFERROR(D21/D18,"-") -> -0.095385213 | E22: =IFERROR(E21/E18,"-") -> 0.0017334165 | F22: =IFERROR(F21/F18,"-") -> - | G22: =IFERROR(G21/G18,"-") -> - | H22: =IFERROR(H21/H18,"-") -> - | I22: =IFERROR(I21/I18,"-") -> - | J22: =IFERROR(J21/J18,"-") -> - | ... N22: =IFERROR(N21/N18,"-") -> -
B23: Forecast vs PY $ | C23: =IFERROR(C20-C19,"-") -> -8596 | D23: =IFERROR(D20-D19,"-") -> 2749 | E23: =IFERROR(E20-E19,"-") -> -6563 | F23: =IFERROR(F20-F19,"-") -> -34186 | G23: =IFERROR(G20-G19,"-") -> -2344 | H23: =IFERROR(H20-H19,"-") -> 5342 | I23: =IFERROR(I20-I19,"-") -> 53821 | J23: =IFERROR(J20-J19,"-") -> 62225 | ... N23: =IFERROR(N20-N19,"-") -> 72014
B24: Forecast vs PY % | C24: =IFERROR(C23/C19,"-") -> -0.030526002 | D24: =IFERROR(D23/D19,"-") -> 0.010727763 | E24: =IFERROR(E23/E19,"-") -> -0.025781437 | F24: =IFERROR(F23/F19,"-") -> -0.11862478 | G24: =IFERROR(G23/G19,"-") -> -0.0088006488 | H24: =IFERROR(H23/H19,"-") -> 0.019884016 | I24: =IFERROR(I23/I19,"-") -> 0.20927447 | J24: =IFERROR(J23/J19,"-") -> 0.24045986 | ... N24: =IFERROR(N23/N19,"-") -> 0.2717653
A26: TOTAL ROTOWIRE | C26: =IFERROR(IF(C4+C11+C18>0,C4+C11+C18,C6+C13+C20),C6+C13+C20) -> 830014.31 | D26: =IFERROR(IF(D4+D11+D18>0,D4+D11+D18,D6+D13+D20),D6+D13+D20) -> 799438.01 | E26: =IFERROR(IF(E4+E11+E18>0,E4+E11+E18,E6+E13+E20),E6+E13+E20) -> 935191.64 | F26: =IFERROR(IF(F4+F11+F18>0,F4+F11+F18,F6+F13+F20),F6+F13+F20) -> 827073 | G26: =IFERROR(IF(G4+G11+G18>0,G4+G11+G18,G6+G13+G20),G6+G13+G20) -> 795554 | H26: =IFERROR(IF(H4+H11+H18>0,H4+H11+H18,H6+H13+H20),H6+H13+H20) -> 826438 | I26: =IFERROR(IF(I4+I11+I18>0,I4+I11+I18,I6+I13+I20),I6+I13+I20) -> 884501 | J26: =IFERROR(IF(J4+J11+J18>0,J4+J11+J18,J6+J13+J20),J6+J13+J20) -> 1196620 | ... N26: =IFERROR(IF(N4+N11+N18>0,N4+N11+N18,N6+N13+N20),N6+N13+N20) -> 1142276 | O26: =SUM(C26:N26) -> 11809984

Sheet RotoWire Notes
A1: 46134 | B1: B2C Subs | C1: Jul26 | D1: Raising slightly under the assumption that all the things we're working on right now will start to click in. July
A2: 46134 | B2: B2C Subs | C2: May26-Jun26 | D2: Lowering slightly just to match ho-hum April, things won't pick up until peak NFL sign-up season'
A3: 46134 | B3: B2B Content | C3: Apr26-Dec26 | D3: Lowering B2B across the board. Simply not picking up as much new business as expected and lost a few key clients. Shannon has a plan to re-double efforts on pro teams
A4: 46127 | B4: B2C Subs | C4: Apr26 | D4: Drop 14K n renewal revenue vs. previous months is slightly worrying
A5: 46127 | B5: B2B Content | C5: Jun26 | D5: Down 8K ... just a slow market right now for new B2B content deals
A6: 46127 | B6: B2B Content | C6: May26 | D6: Down 8K ... just a slow market right now for new B2B content deals
A7: 46127 | B7: B2B Content | C7: Apr26 | D7: Down 8K ... just a slow market right now for new B2B content deals
A8: 46120 | B8: B2C Subs | C8: Apr26 | D8: Down 5K because we made a big push to grab $$$ in the last week of March, so there's a trickle-down slightly adverse effect on NEW SUBS for early April
A9: 46120 | B9: B2B Content | C9: Jun26 | D9: Down 20K to account for slower-than-expected growth on new B2B API deals this year
A10: 46120 | B10: B2B Content | C10: May26 | D10: Down 10K to account for slower-than-expected growth on new B2B API deals this year
A11: 46112 | B11: B2B Content | C11: Mar26 | D11: Down 10K to account for some renewing contracts held up ... we will pick up this revenue in future months
A12: 46112 | B12: B2B Content | C12: May26 | D12: Dropped by 15K to meet realities of losing a few B2B partners and not a huge demand in the short term
... A36: 46037 | B36: B2B Content | C36: Jan26 | D36: Down $281,000 to $273,000
A39: 2025 data
H40: Q1 | T40: Q1 Total | X40: Q2 | AJ40: Q2 Total | AN40: Q3 | BD40: Q3 Total | BH40: Q4 | BT40: Q4 Total
D41: YTD | H41: Jan | L41: Feb | P41: Mar | T41: Q1 | X41: Apr | AB41: May | AF41: Jun | AJ41: Q2 | AN41: Jul | AR41: Aug | AX41: Sep | BD41: Q3 | BH41: Oct | BL41: Nov | BP41: Dec | BT41: Q4
D42: Actual | E42: Acutal 24' | F42: Target | G42: Forecast | H42: Actual | I42: Acutal 24' | J42: Target | K42: Forecast | L42: Actual | M42: Acutal 24' | N42: Target | O42: Forecast | P42: Actual | Q42: Acutal 24' | R42: Target | S42: Forecast | T42: Actual | U42: Acutal 24' | V42: Target | W42: Forecast | X42: Actual | Y42: Acutal 24' | Z42: Target | AA42: Forecast | AB42: Actual | AC42: Acutal 24' | AD42: Target | AE42: Forecast | AF42: Actual | AG42: Acutal 24' | AH42: Target | AI42: Forecast | AJ42: Actual | AK42: Acutal 24' | AL42: Target | AM42: Forecast | AN42: Actual | AO42: Acutal 24' | AP42: Target | AQ42: Forecast | AR42: Actual | AS42: Acutal 24' | AT42: Actual | AU42: Acutal 24' | AV42: Target | AW42: Forecast | AX42: Actual | AY42: Acutal 24' | AZ42: Actual | BA42: Acutal 24' | BB42: Target | BC42: Forecast | BD42: Actual | BE42: Acutal 24' | BF42: Target | BG42: Forecast | BH42: Actual | BI42: Acutal 24' | BJ42: Target | BK42: Forecast | BL42: Actual | BM42: Acutal 24' | BN42: Target | BO42: Forecast | BP42: Actual | BQ42: Acutal 24' | BR42: Target | BS42: Forecast | BT42: Actual | BU42: Acutal 24' | BV42: Target | BW42: Forecast
B43: TOTAL | C43: Rotowire | D43: =D44+D47+D48 -> 4823881 | F43: =SUM(F44:F48) -> #VALUE! | G43: =G44+G47+G48 -> 10213856 | H43: =H44+H47+H48 -> 791440 | I43: =I44+I47+I48 -> 709020 | J43: =SUM(J44:J48) -> 0 | K43: =K44+K47+K48 -> 835500 | L43: =L44+L47+L48 -> 756347 | N43: =SUM(N44:N48) -> 0 | O43: =O44+O47+O48 -> 796000 | P43: =P44+P47+P48 -> 883938 | R43: =SUM(R44:R48) -> 0 | S43: =S44+S47+S48 -> 938000 | T43: =T44+T47+T48 -> 2431725 | V43: =SUM(V44:V48) -> 0 | W43: =W44+W47+W48 -> 2569500 | X43: =X44+X47+X48 -> 879601 | Z43: =SUM(Z44:Z48) -> 0 | AA43: =AA44+AA47+AA48 -> 803500 | AB43: =AB44+AB47+AB48 -> 745569 | AD43: =AD44+AD47+AD48 -> #VALUE! | AE43: =AE44+AE47+AE48 -> 745000 | AF43: =AF44+AF47+AF48 -> 766986 | AG43: =AG44+AG47+AG48 -> 727136 | AH43: =SUM(AH44:AH48) -> 0 | AI43: =AI44+AI47+AI48 -> 743500 | AJ43: =AJ44+AJ47+AJ48 -> 2392156 | AL43: =SUM(AL44:AL48) -> 0 | AM43: =AM44+AM47+AM48 -> 2292000 | AN43: =AN44+AN47+AN48 -> 782551 | AO43: =AO44+AO47+AO48 -> 714061 | AP43: =SUM(AP44:AP48) -> 0 | AQ43: =AQ44+AQ47+AQ48 -> 759000 | AU43: =AU44+AU47+AU48 -> 1035795 | AV43: =SUM(AV44:AV48) -> 0 | AW43: =AW44+AW47+AW48 -> 969651 | BB43: =SUM(BB44:BB48) -> 0 | BC43: =BC44+BC47+BC48 -> 944296 | BF43: =SUM(BF44:BF48) -> 0 | BG43: =BG44+BG47+BG48 -> 2672947 | BH43: =BH44+BH47+BH48 -> 906023.02 | BJ43: =SUM(BJ44:BJ48) -> 0 | BK43: =BK44+BK47+BK48 -> 878346 | BL43: =BL44+BL47+BL48 -> 945198.27 | BM43: =BM44+BM47+BM48 -> 862631 | BN43: =SUM(BN44:BN48) -> 0 | BO43: =BO44+BO47+BO48 -> 914692 | BP43: =BP44+BP47+BP48 -> 964747 | BR43: =SUM(BR44:BR48) -> 0 | BS43: =BS44+BS47+BS48 -> 886371 | BV43: =SUM(BV44:BV48) -> 0 | BW43: =BW44+BW47+BW48 -> 2679409
B44: Rotowire | C44: Rotowire - B2C Subs | D44: =SUM(T44+AJ44+BD44+BT44) -> 2716044 | F44: =SUM(V44+AL44+BF44+BV44) -> #VALUE! | G44: =SUM(W44+AM44+BG44+BW44) -> 5876971 | H44: 475862 | I44: 402792 | J44: =IFERROR(VLOOKUP($C44,[1]vlookup!$B:$N,2,FALSE),"") | K44: =SUM(K45:K46) -> 508000 | L44: 440769 | N44: =IFERROR(VLOOKUP($C44,[1]vlookup!$B:$N,3,FALSE),"") | O44: =SUM(O45:O46) -> 462000 | P44: 523542 | R44: =IFERROR(VLOOKUP($C44,[1]vlookup!$B:$N,4,FALSE),"") | S44: =SUM(S45:S46) -> 563000 | T44: =IFERROR(SUM(H44+L44+P44),"") -> 1440173 | V44: =IFERROR(SUM(J44+N44+R44),"") | W44: =IFERROR(SUM(K44+O44+S44),"") -> 1533000 | X44: 456408 | Z44: =IFERROR(VLOOKUP($C44,[1]vlookup!$B:$N,5,FALSE),"") | AA44: =SUM(AA45:AA46) -> 442500 | AB44: 413875 | AD44: =IFERROR(VLOOKUP($C44,[1]vlookup!$B:$N,6,FALSE),"") | AE44: =AE45+AE46 -> 416000 | AF44: =SUM(AF45:AF46) -> 405588 | AG44: =SUM(AG45:AG46) -> 393059 | AH44: =IFERROR(VLOOKUP($C44,[1]vlookup!$B:$N,7,FALSE),"") | AI44: =AI45+AI46 -> 404000 | AJ44: =IFERROR(SUM(X44+AB44+AF44),"") -> 1275871 | AL44: =IFERROR(SUM(Z44+AD44+AH44),"") | AM44: =IFERROR(SUM(AA44+AE44+AI44),"") -> 1262500 | AN44: 413273 | AO44: =SUM(AO45:AO46) -> 424318 | AP44: =IFERROR(VLOOKUP($C44,[1]vlookup!$B:$N,8,FALSE),"") | AQ44: =AQ45+AQ46 -> 409000 | AT44: =SUM(AT45:AT46) -> 487745 | AU44: =SUM(AU45:AU46) -> 675234 | AV44: =IFERROR(VLOOKUP($C44,[1]vlookup!$B:$N,9,FALSE),"") | AW44: =AW45+AW46 -> 582651 | AZ44: =SUM(AZ45:AZ46) -> 584456 | BA44: =SUM(BA45:BA46) -> 505913 | BB44: =IFERROR(VLOOKUP($C44,[1]vlookup!$B:$N,10,FALSE),"") | BC44: =BC45+BC46 -> 564296 | BF44: =IFERROR(SUM(AP44+AV44+BB44),"") | BG44: =IFERROR(SUM(AQ44+AW44+BC44),"") -> 1555947 | BH44: =SUM(BH45:BH46) -> 525518.02 | BJ44: =IFERROR(VLOOKUP($C44,[1]vlookup!$B:$N,11,FALSE),"") | BK44: =BK45+BK46 -> 513346 | BL44: =SUM(BL45:BL46) -> 499581.87 | BM44: =SUM(BM45:BM46) -> 460439 | BN44: =IFERROR(VLOOKUP($C44,[1]vlookup!$B:$N,12,FALSE),"") | BO44: =BO45+BO46 -> 522807 | BP44: 576820 | BR44: =IFERROR(VLOOKUP($C44,[1]vlookup!$B:$N,13,FALSE),"") | BS44: =BS45+BS46 -> 489371 | BV44: =IFERROR(SUM(BJ44+BN44+BR44),"") | BW44: =IFERROR(SUM(BK44+BO44+BS44),"") -> 1525524
